Workbook

Sheet WORKLOG AWS FCJ
A2: Day | B2: Task | C2: Describe | D2: Labels | E2: State | F2: Start date | G2: Due date | H2: Deliverable | I2: Notes
A3: 45777 | E3: To do
A4: 45778 | E4: To do
A5: 45779 | E5: To do
A6: 45780 | E6: To do
A7: 45781 | E7: To do
A8: 45782 | E8: To do
A9: 45783 | E9: To do
A10: 45784 | E10: To do
A11: 45785 | E11: To do
A12: 45786 | E12: To do
A13: 45787 | E13: To do
A14: 45788 | E14: To do
... A79: 45853 | E79: To do

Sheet Daily Report
A1: Date | B1: Week # | C1: Check-in | D1: Check-out | E1: Total Hours | F1: Daily Goals | G1: Tasks Completed | H1: Challenges | I1: Solutions | J1: Tomorrow's Plan | K1: Documents | L1: Note | M1: Mentor Feedback
A2: 45789 | B2: 1 | C2: 19:00 | D2: 22:00 | E2: =IF(AND(D2<>"",C2<>""),(D2-C2)*24,"") -> 3 | F2: Xem các video thuộc Week 01, ghi chú lại kiến thức đã học | G2: Tìm hiểu kiến trúc AWS và Điện toán đám mây | H2: N/A | I2: N/A | J2: Hoàn thành các nội dung thuộc Week 1 | K2: Week01
A3: 45790 | B3: 1 | C3: 19:00 | D3: 22:00 | E3: =IF(AND(D3<>"",C3<>""),(D3-C3)*24,"") -> 3 | F3: Xem các video thuộc Week 01, ghi chú lại kiến thức đã học | G3: Tìm hiểu về AWS Management Console và hạ tầng của AWS | H3: N/A | I3: N/A | J3: Hoàn thành các nội dung thuộc Week 1 | K3: Week01
A4: 45791 | B4: 1 | C4: 19:00 | D4: 22:00 | E4: =IF(AND(D4<>"",C4<>""),(D4-C4)*24,"") -> 3 | F4: Xem các video thuộc Week 01, ghi chú lại kiến thức đã học | G4: Thực hành Lab07 và Lab09 | H4: N/A | I4: N/A | J4: Hoàn thành các nội dung thuộc Week 1 | K4: Week01
A5: 45792 | B5: 1 | C5: 19:00 | D5: 22:00 | E5: =IF(AND(D5<>"",C5<>""),(D5-C5)*24,"") -> 3 | F5: Xem các video thuộc Week 02 Ghi chú lại kiến thức đã học | G5: Tìm hiểu về EC2 Ghi chép chi tiết nội dung hiểu được | H5: N/A | I5: N/A | J5: Hoàn thành các nội dung thuộc Week 02 | K5: Week02
A6: 45793 | B6: 1 | C6: 19:00 | D6: 22:00 | E6: =IF(AND(D6<>"",C6<>""),(D6-C6)*24,"") -> 3 | F6: Xem các video thuộc Week 02 Ghi chú lại kiến thức đã học | G6: Thực hành Lab03, 10, và 19 Ghi chép nội dung đã thực hiện | H6: N/A | I6: N/A | J6: Hoàn thành các nội dung thuộc Week 02 | K6: Week02
A7: 45794 | B7: 1 | E7: =IF(AND(D7<>"",C7<>""),(D7-C7)*24,"")
A8: 45795 | B8: 1 | E8: =IF(AND(D8<>"",C8<>""),(D8-C8)*24,"")
A9: 45796 | B9: 2 | C9: 19:00 | D9: 22:00 | E9: =IF(AND(D9<>"",C9<>""),(D9-C9)*24,"") -> 3 | F9: Xem các video thuộc Week 02 Ghi chú lại kiến thức đã học | G9: Thực hành Lab 10, Ghi chép nội dung đã thực hiện | H9: N/A | I9: N/A | J9: Hoàn thành các nội dung thuộc Week 02 | K9: Week02
A10: 45797 | B10: 2 | C10: 09:00 | D10: 17:00 | E10: =IF(AND(D10<>"",C10<>""),(D10-C10)*24,"") -> 8 | F10: Xem các video thuộc Week 02 Ghi chú lại kiến thức đã học | G10: Thực hành Lab 13, Ghi chép nội dung đã thực hiện | H10: N/A | I10: N/A | J10: Hoàn thành các nội dung thuộc Week 03 | K10: Week03
A11: 45798 | B11: 2 | C11: 09:00 | D11: 13:00 | E11: =IF(AND(D11<>"",C11<>""),(D11-C11)*24,"") -> 4 | F11: AWS Data Foundation Workshop
A12: 45799 | B12: 2 | C12: 19:00 | D12: 22:00 | E12: =IF(AND(D12<>"",C12<>""),(D12-C12)*24,"") -> 3 | F12: Xem các video thuộc Week 03 Ghi chú lại kiến thức đã học | G12: Thực hành Lab 14 Ghi chép nội dung đã thực hiện | H12: N/A | I12: N/A | J12: Hoàn thành các nội dung thuộc Week 03 | K12: Week03
A13: 45800 | B13: 2 | C13: 19:00 | D13: 22:00 | E13: =IF(AND(D13<>"",C13<>""),(D13-C13)*24,"") -> 3 | F13: Xem các video thuộc Week 03 Ghi chú lại kiến thức đã học | G13: Tìm hiểu về S3 Ghi chép chi tiết nội dung hiểu được | H13: N/A | I13: N/A | J13: Hoàn thành các nội dung thuộc Week 03 | K13: Week03
A14: 45801 | B14: 2 | E14: =IF(AND(D14<>"",C14<>""),(D14-C14)*24,"")
A15: 45802 | B15: 2 | E15: =IF(AND(D15<>"",C15<>""),(D15-C15)*24,"")
A16: 45803 | B16: 3 | C16: 19:00 | D16: 22:00 | E16: =IF(AND(D16<>"",C16<>""),(D16-C16)*24,"") -> 3 | F16: Xem các video thuộc Week 04 Ghi chú lại kiến thức đã học | G16: Thực hành Lab 14 thuộc Module 4 Ghi chép nội dung đã thực hiện | H16: Máy ảo bị đứng ở bước install Ubuntu | I16: N/A | J16: Hoàn thành các nội dung thuộc Week 04 | K16: Week04 - S3
A17: 45804 | B17: 3 | C17: 19:00 | D17: 22:00 | E17: =IF(AND(D17<>"",C17<>""),(D17-C17)*24,"") -> 3 | F17: Xem các video thuộc Week 04 Ghi chú lại kiến thức đã học | G17: Thực hành Lab 14 thuộc Module 4 Ghi chép nội dung đã thực hiện | H17: Máy ảo bị đứng ở bước install Ubuntu | I17: N/A | J17: Hoàn thành các nội dung thuộc Week 04 | K17: Week04 - S3
A18: 45805 | B18: 3 | C18: 19:00 | D18: 22:00 | E18: =IF(AND(D18<>"",C18<>""),(D18-C18)*24,"") -> 3 | F18: Thực hành các lab thuộc Week 04 Ghi chú lại kiến thức đã học | G18: Thực hành Lab 14 thuộc Module 4 Ghi chép nội dung đã thực hiện | H18: Máy ảo bị đứng ở bước install Ubuntu | I18: Nâng RAM cho máy ảo | J18: Hoàn thành các nội dung thuộc Week 04 | K18: Week04 - S3
A19: 45806 | B19: 3 | C19: 9:00 | D19: 17:00 | E19: =IF(AND(D19<>"",C19<>""),(D19-C19)*24,"") -> 8 | F19: Thực hành các lab thuộc Week 04 Ghi chú lại kiến thức đã học | G19: Thực hành Lab 14 thuộc Module 4 Ghi chép nội dung đã thực hiện | H19: Máy ảo vẫn bị đứng ở bước install Ubuntu | I19: Tải iso của Ubuntu bản mới nhất, nâng RAM cho máy ảo | J19: Hoàn thành các nội dung thuộc Week 04 | K19: Week04 - S3
A20: 45807 | B20: 3 | E20: =IF(AND(D20<>"",C20<>""),(D20-C20)*24,"")
A21: 45808 | B21: 3 | E21: =IF(AND(D21<>"",C21<>""),(D21-C21)*24,"")
A22: 45809 | B22: 3 | E22: =IF(AND(D22<>"",C22<>""),(D22-C22)*24,"")
A23: 45810 | B23: 4 | C23: 19:00 | D23: 22:00 | E23: =IF(AND(D23<>"",C23<>""),(D23-C23)*24,"") -> 3 | F23: Thực hành các lab thuộc Week 04 Ghi chú lại kiến thức đã học | G23: Làm bài test thuộc Module 04 | J23: Hoàn thành các nội dung thuộc Week 04 | K23: Week04 - S3
A24: 45811 | B24: 4 | C24: 19:00 | D24: 22:00 | E24: =IF(AND(D24<>"",C24<>""),(D24-C24)*24,"") -> 3 | F24: Xem các video thuộc Week 05 Ghi chú lại kiến thức đã học | G24: Ghi chép nội dung lý thuyết week05 | J24: Hoàn thành các nội dung lý thuyết thuộc Week 05 | K24: Week05 - Security
A25: 45812 | B25: 4 | C25: 19:00 | D25: 22:00 | E25: =IF(AND(D25<>"",C25<>""),(D25-C25)*24,"") -> 3 | F25: Xem các video thuộc Week 05 Ghi chú lại kiến thức đã học | G25: Ghi chép nội dung lý thuyết week05 | J25: Hoàn thành các nội dung lý thuyết thuộc Week 05 | K25: Week05 - Security
A26: 45813 | B26: 4 | C26: 19:00 | D26: 22:00 | E26: =IF(AND(D26<>"",C26<>""),(D26-C26)*24,"") -> 3
A27: 45814 | B27: 4 | C27: 19:00 | D27: 22:00 | E27: =IF(AND(D27<>"",C27<>""),(D27-C27)*24,"") -> 3
A28: 45815 | B28: 4 | E28: =IF(AND(D28<>"",C28<>""),(D28-C28)*24,"")
A29: 45816 | B29: 4 | E29: =IF(AND(D29<>"",C29<>""),(D29-C29)*24,"")
A30: 45817 | B30: 5 | E30: =IF(AND(D30<>"",C30<>""),(D30-C30)*24,"")
A31: 45818 | B31: 5 | E31: =IF(AND(D31<>"",C31<>""),(D31-C31)*24,"")
A32: 45819 | B32: 5 | E32: =IF(AND(D32<>"",C32<>""),(D32-C32)*24,"")
A33: 45820 | B33: 5 | C33: 8:30 | D33: 17:00 | E33: =IF(AND(D33<>"",C33<>""),(D33-C33)*24,"") -> 8.5 | F33: Lên văn phòng
A34: 45821 | B34: 5 | E34: =IF(AND(D34<>"",C34<>""),(D34-C34)*24,"")
A35: 45822 | B35: 5 | C35: 9:00 | D35: 12:00 | E35: =IF(AND(D35<>"",C35<>""),(D35-C35)*24,"") -> 3 | F35: First Cloud Sercurity Journey | G35: Ghi chú về các dịch vụ và tìm hiểu về các dịch vụ, hoạt động được giới thiệu | H35: Một số vấn đề chưa được ghi rõ | I35: Về nhà tìm hiểu thêm về thông tin được đưa ra trong sự kiện | K35: Event
A36: 45823 | B36: 5 | E36: =IF(AND(D36<>"",C36<>""),(D36-C36)*24,"")
A37: 45824 | B37: 6 | E37: =IF(AND(D37<>"",C37<>""),(D37-C37)*24,"")
A38: 45825 | B38: 6 | E38: =IF(AND(D38<>"",C38<>""),(D38-C38)*24,"")
A39: 45826 | B39: 6 | E39: =IF(AND(D39<>"",C39<>""),(D39-C39)*24,"")
A40: 45827 | B40: 6 | C40: 9:00 | D40: 17:00 | E40: =IF(AND(D40<>"",C40<>""),(D40-C40)*24,"") -> 8 | F40: Lên văn phòng Chuẩn bị workshop | H40: NA | I40: NA | J40: Tiếp tục chuẩn bị workshop | K40: Week06 - Workshop
...

Sheet Weekly Summary Report
A1: Week # | B1: Day | C1: Tổng số giờ làm việc | D1: Thành tựu chính | E1: Dịch vụ AWS đã học | F1: Kỹ năng đạt được | G1: Mục tiêu tuần tới | H1: Phản hồi của mentor
A2: 1 | B2: 15/04/2025 - 20/04/2025 | C2: =SUMIFS('Daily Report'!E:E,'Daily Report'!B:B,'Weekly Summary Report'!$A$2:$A$13) -> 15
A3: 2 | B3: 21/04/2025 - 27/04/2025 | C3: =SUMIFS('Daily Report'!E:E,'Daily Report'!B:B,'Weekly Summary Report'!$A$2:$A$13) -> 21
A4: 3 | B4: 28/04/2025 - 04/05/2025 | C4: =SUMIFS('Daily Report'!E:E,'Daily Report'!B:B,'Weekly Summary Report'!$A$2:$A$13) -> 17
A5: 4 | B5: 05/05/2025 - 11/05/2025 | C5: =SUMIFS('Daily Report'!E:E,'Daily Report'!B:B,'Weekly Summary Report'!$A$2:$A$13) -> 15
A6: 5 | B6: 12/05/2025 - 18/05/2025 | C6: =SUMIFS('Daily Report'!E:E,'Daily Report'!B:B,'Weekly Summary Report'!$A$2:$A$13) -> 11.5
A7: 6 | B7: 19/05/2025 - 25/05/2025 | C7: =SUMIFS('Daily Report'!E:E,'Daily Report'!B:B,'Weekly Summary Report'!$A$2:$A$13) -> 8
A8: 7 | B8: 26/05/2025 - 01/06/2025 | C8: =SUMIFS('Daily Report'!E:E,'Daily Report'!B:B,'Weekly Summary Report'!$A$2:$A$13) -> 40
A9: 8 | B9: 02/06/2025 - 08/06/2025 | C9: =SUMIFS('Daily Report'!E:E,'Daily Report'!B:B,'Weekly Summary Report'!$A$2:$A$13) -> 56
A10: 9 | B10: 09/06/2025 - 15/06/2025 | C10: =SUMIFS('Daily Report'!E:E,'Daily Report'!B:B,'Weekly Summary Report'!$A$2:$A$13) -> 40
A11: 10 | B11: 16/06/2025 - 22/06/2025 | C11: =SUMIFS('Daily Report'!E:E,'Daily Report'!B:B,'Weekly Summary Report'!$A$2:$A$13) -> 32
A12: 11 | B12: 23/06/2025 - 29/06/2025 | C12: =SUMIFS('Daily Report'!E:E,'Daily Report'!B:B,'Weekly Summary Report'!$A$2:$A$13) -> 0
A13: 12 | B13: 30/06/2025 - 06/07/2025 | C13: =SUMIFS('Daily Report'!E:E,'Daily Report'!B:B,'Weekly Summary Report'!$A$2:$A$13) -> 0

Sheet SELF-ASSESSMENT
A2: Thông tin cơ bản
A3: Họ và tên | B3: Lưu Thành Đạt
A4: MSSV | B4: 2180607420
A5: Số điện thoại | B5: 0399645074
A6: Email | B6: rhysterluu@gmail.com
A7: Vị trí thực tập
A8: Người hướng dẫn | B8: Nguyễn Gia Hưng, Văn Hoàng Kha
A9: Định hướng phát triển
A10: Nhiệm vụ phân công
A11: Link Notion
A12: Link Github
A13: Thời gian thực tập
A14: Ngày bắt đầu | B14: 45760
A15: Ngày kết thúc dự kiến | B15: 45853
A16: Tổng số tuần
A17: Số giờ yêu cầu mỗi tuần
A18: Bảng theo dõi tiến độ
A19: Tổng số giờ đã làm việc | B19: =SUM('Daily Report'!E:E) -> 255.5
A20: Tỷ lệ hoàn thành
A21: Số ngày đã thực tập
A22: Nội dung tự đánh giá
A23: 1. Thái độ, chấp hành kỷ luật
A24: 2. Kỹ năng mềm
A25: 3. Kiến thức chuyên môn
A26: Thành tích thực tập
A36: Công việc khác

Sheet WORKLOG WORKSHOP
A2: Day | B2: Task | C2: Describe | D2: Labels | E2: State | F2: Start date | G2: Due date | H2: Deliverable
